<?xml version="1.0" ?>
<!-- =================================================================================== -->
<!-- |    This document was autogenerated by xacro from install/robot_description/share/robot_description/urdf/robot.urdf.xacro | -->
<!-- |    EDITING THIS FILE BY HAND IS NOT RECOMMENDED                                 | -->
<!-- =================================================================================== -->
<robot name="simple_robot">
  <!-- Base link -->
  <link name="base_link">
    <visual>
      <geometry>
        <box size="0.5 0.3 0.2"/>
      </geometry>
      <material name="blue"/>
    </visual>
  </link>
  <!-- Wheels -->
  <link name="wheel_left">
    <visual>
      <geometry>
        <cylinder length="0.02" radius="0.05"/>
      </geometry>
      <material name="black"/>
    </visual>
  </link>
  <link name="wheel_right">
    <visual>
      <geometry>
        <cylinder length="0.02" radius="0.05"/>
      </geometry>
      <material name="black"/>
    </visual>
  </link>
  <!-- Camera -->
  <link name="camera">
    <visual>
      <geometry>
        <box size="0.1 0.05 0.05"/>
      </geometry>
      <material name="grey"/>
    </visual>
  </link>
  <!-- Joints -->
  <joint name="base_to_left_wheel" type="continuous">
    <parent link="base_link"/>
    <child link="wheel_left"/>
    <origin xyz="-0.2 0 0"/>
    <axis xyz="0 1 0"/>
  </joint>
  <joint name="base_to_right_wheel" type="continuous">
    <parent link="base_link"/>
    <child link="wheel_right"/>
    <origin xyz="0.2 0 0"/>
    <axis xyz="0 1 0"/>
  </joint>
  <joint name="base_to_camera" type="fixed">
    <parent link="base_link"/>
    <child link="camera"/>
    <origin xyz="0 0 0.15"/>
  </joint>
</robot>
